<?xml version="1.0"?>
<robot xmlns:xacro="http://www.ros.org/wiki/xacro">

    <xacro:include filename="inertial_macros.xacro"/>

    <xacro:macro name="revolut_wheel_effort" params="name xyz rpy length radius mass">

        <link name="${name}_link">
            <visual>
                <geometry>
                    <cylinder length="${length}" radius="${radius}"/>
                </geometry>
                <material name="black"/>
            </visual>
            <collision>
                <geometry>
                    <cylinder length="${length}" radius="${radius}"/>
                </geometry>
            </collision>
            <xacro:inertial_cylinder mass="${mass}" length="${length}" radius="${radius}">
                <origin xyz="0 0 0" rpy="0 0 0"/>
            </xacro:inertial_cylinder>
        </link>

        <joint name="${name}_joint" type="continuous">
            <parent link="base_footprint"/>
            <child link="${name}_link"/>
            <origin xyz="${xyz}" rpy="${pi/2} 0 0"/>
            <limit effort="200" velocity="1000"/>
            <axis xyz="0 0 -1"/>
        </joint>

        <gazebo reference="${name}_link">
            <material>Gazebo/Black</material>
            <kp>1000000.0</kp>
            <kd>1.0</kd>
            <mu1>1.0</mu1>
            <mu2>1.0</mu2>
        </gazebo>
    </xacro:macro>


</robot>